server: --server http://127.0.0.1:32400
username: --username radrud@gmail.com
servername: --servername Mortaire-Damien
Traceback (most recent call last):
  File "/usr/lib/python3/dist-packages/urllib3/connectionpool.py", line 594, in urlopen
    chunked=chunked)
  File "/usr/lib/python3/dist-packages/urllib3/connectionpool.py", line 391, in _make_request
    six.raise_from(e, None)
  File "<string>", line 2, in raise_from
  File "/usr/lib/python3/dist-packages/urllib3/connectionpool.py", line 387, in _make_request
    httplib_response = conn.getresponse()
  File "/usr/lib/python3.5/http/client.py", line 1198, in getresponse
    response.begin()
  File "/usr/lib/python3.5/http/client.py", line 297, in begin
    version, status, reason = self._read_status()
  File "/usr/lib/python3.5/http/client.py", line 258, in _read_status
    line = str(self.fp.readline(_MAXLINE + 1), "iso-8859-1")
  File "/usr/lib/python3.5/socket.py", line 576, in readinto
    return self._sock.recv_into(b)
ConnectionResetError: [Errno 104] Connection reset by peer

During handling of the above exception, another exception occurred:

Traceback (most recent call last):
  File "/usr/lib/python3/dist-packages/requests/adapters.py", line 423, in send
    timeout=timeout
  File "/usr/lib/python3/dist-packages/urllib3/connectionpool.py", line 643, in urlopen
    _stacktrace=sys.exc_info()[2])
  File "/usr/lib/python3/dist-packages/urllib3/util/retry.py", line 334, in increment
    raise six.reraise(type(error), error, _stacktrace)
  File "/usr/lib/python3/dist-packages/six.py", line 685, in reraise
    raise value.with_traceback(tb)
  File "/usr/lib/python3/dist-packages/urllib3/connectionpool.py", line 594, in urlopen
    chunked=chunked)
  File "/usr/lib/python3/dist-packages/urllib3/connectionpool.py", line 391, in _make_request
    six.raise_from(e, None)
  File "<string>", line 2, in raise_from
  File "/usr/lib/python3/dist-packages/urllib3/connectionpool.py", line 387, in _make_request
    httplib_response = conn.getresponse()
  File "/usr/lib/python3.5/http/client.py", line 1198, in getresponse
    response.begin()
  File "/usr/lib/python3.5/http/client.py", line 297, in begin
    version, status, reason = self._read_status()
  File "/usr/lib/python3.5/http/client.py", line 258, in _read_status
    line = str(self.fp.readline(_MAXLINE + 1), "iso-8859-1")
  File "/usr/lib/python3.5/socket.py", line 576, in readinto
    return self._sock.recv_into(b)
requests.packages.urllib3.exceptions.ProtocolError: ('Connection aborted.', ConnectionResetError(104, 'Connection reset by peer'))

During handling of the above exception, another exception occurred:

Traceback (most recent call last):
  File "/usr/local/bin/plexurl", line 11, in <module>
    load_entry_point('plexurl', 'console_scripts', 'plexurl')()
  File "/home/idk/Downloads/plexurl-old/plexurl/plexurl.py", line 324, in main
    server = get_server(args.server, username=args.username, password=args.password, servername=args.servername)
  File "/home/idk/Downloads/plexurl-old/plexurl/plexurl.py", line 136, in get_server
    return PlexServer(uri)
  File "/usr/local/lib/python3.5/dist-packages/PlexAPI-3.0.3-py3.5.egg/plexapi/server.py", line 103, in __init__
  File "/usr/local/lib/python3.5/dist-packages/PlexAPI-3.0.3-py3.5.egg/plexapi/server.py", line 341, in query
  File "/usr/lib/python3/dist-packages/requests/sessions.py", line 501, in get
    return self.request('GET', url, **kwargs)
  File "/usr/lib/python3/dist-packages/requests/sessions.py", line 488, in request
    resp = self.send(prep, **send_kwargs)
  File "/usr/lib/python3/dist-packages/requests/sessions.py", line 609, in send
    r = adapter.send(request, **kwargs)
  File "/usr/lib/python3/dist-packages/requests/adapters.py", line 473, in send
    raise ConnectionError(err, request=request)
requests.exceptions.ConnectionError: ('Connection aborted.', ConnectionResetError(104, 'Connection reset by peer'))
